{
  "id": "PYSEC-2017-122",
  "modified": "2024-11-21T14:22:46.411851Z",
  "published": "2017-07-17T13:18:00Z",
  "withdrawn": "2024-11-22T04:37:04Z",
  "details": "There is a Segmentation fault in the XmpParser::terminate() function in Exiv2 0.26, related to an exit call. A Crafted input will lead to a remote denial of service attack.",
  "affected": [
    {
      "package": {
        "ecosystem": "PyPI",
        "name": "exiv2",
        "purl": "pkg:pypi/exiv2"
      },
      "ranges": [
        {
          "type": "ECOSYSTEM",
          "events": [
            {
              "introduced": "0"
            }
          ]
        }
      ],
      "versions": [
        "0.1",
        "0.11.0",
        "0.11.1",
        "0.11.2",
        "0.11.3",
        "0.12.0",
        "0.12.1",
        "0.13.0",
        "0.13.1",
        "0.13.2",
        "0.14.0",
        "0.14.1",
        "0.15.0",
        "0.16.0",
        "0.16.1",
        "0.16.2",
        "0.16.2.post1",
        "0.16.3",
        "0.16.3.post1",
        "0.17.0",
        "0.17.1",
        "0.2",
        "0.3",
        "0.3.1"
      ],
      "database_specific": {
        "source": "https://github.com/pypa/advisory-database/blob/main/vulns/exiv2/PYSEC-2017-122.yaml"
      }
    }
  ],
  "references": [
    {
      "type": "REPORT",
      "url": "https://bugzilla.redhat.com/show_bug.cgi?id=1470950"
    }
  ]
}