{
  "id": "MAL-2024-5814",
  "modified": "2024-10-24T01:01:59Z",
  "published": "2024-06-25T13:41:00Z",
  "aliases": [
    "SNYK-PYTHON-PYTHONCRYPTPKGSV2-5591187",
    "SNYK-PYTHON-PYTHONCRYPTPKGSV2-5932135"
  ],
  "summary": "Malicious code in pythoncryptpkgsv2 (PyPI)",
  "details": "\n---\n_-= Per source details. Do not edit below this line.=-_\n",
  "affected": [
    {
      "package": {
        "ecosystem": "PyPI",
        "name": "pythoncryptpkgsv2",
        "purl": "pkg:pypi/pythoncryptpkgsv2"
      },
      "versions": [
        "1.1.0",
        "3.3.3",
        "1.0.0"
      ],
      "database_specific": {
        "source": "https://github.com/ossf/malicious-packages/blob/main/osv/malicious/pypi/pythoncryptpkgsv2/MAL-2024-5814.json"
      }
    }
  ],
  "references": [
    {
      "type": "ADVISORY",
      "url": "https://security.snyk.io/vuln/SNYK-PYTHON-PYTHONCRYPTPKGSV2-5932135"
    },
    {
      "type": "ADVISORY",
      "url": "https://security.snyk.io/vuln/SNYK-PYTHON-PYTHONCRYPTPKGSV2-5591187"
    },
    {
      "type": "ARTICLE",
      "url": "https://blog.phylum.io/respawning-malware-persists-on-pypi/"
    },
    {
      "type": "ARTICLE",
      "url": "https://medium.com/checkmarx-security/the-evolutionary-tale-of-a-persistent-python-threat-d19196d4ed15"
    }
  ]
}