{
  "Identifier": "CVE-2022-23580",
  "PackageSlug": "pypi/tensorflow-cpu",
  "Title": "Abort caused by allocating a vector that is too large in Tensorflow",
  "Description": "During shape inference, TensorFlow can [allocate a large vector](https://github.com/tensorflow/tensorflow/blob/a1320ec1eac186da1d03f033109191f715b2b130/tensorflow/core/framework/shape_inference.cc#L788-L790) based on a value from a tensor controlled by the user:\n\n```cc\nconst auto num_dims = Value(shape_dim);\nstd::vector\u003cDimensionHandle\u003e dims;\ndims.reserve(num_dims);\n```",
  "Date": "2024-11-07",
  "Pubdate": "2022-02-07",
  "AffectedRange": "\u003c2.5.3||\u003e=2.6.0,\u003c2.6.3||\u003e=2.7.0,\u003c2.7.1||==2.7.0",
  "FixedVersions": [
    "2.5.3",
    "2.6.3",
    "2.7.1"
  ],
  "AffectedVersions": "All versions before 2.5.3, all versions starting from 2.6.0 before 2.6.3, all versions starting from 2.7.0 before 2.7.1, version 2.7.0",
  "NotImpacted": "",
  "Solution": "Upgrade to versions 2.5.3, 2.6.3, 2.7.1 or above.",
  "Urls": [
    "https://nvd.nist.gov/vuln/detail/CVE-2022-23580",
    "https://github.com/advisories/GHSA-627q-g293-49q7",
    "https://github.com/tensorflow/tensorflow/security/advisories/GHSA-627q-g293-49q7",
    "https://github.com/tensorflow/tensorflow/commit/1361fb7e29449629e1df94d44e0427ebec8c83c7",
    "https://github.com/pypa/advisory-database/tree/main/vulns/tensorflow-cpu/PYSEC-2022-89.yaml",
    "https://github.com/pypa/advisory-database/tree/main/vulns/tensorflow-gpu/PYSEC-2022-144.yaml",
    "https://github.com/tensorflow/tensorflow",
    "https://github.com/tensorflow/tensorflow/blob/a1320ec1eac186da1d03f033109191f715b2b130/tensorflow/core/framework/shape_inference.cc#L788-L790"
  ],
  "CvssV2": "AV:N/AC:L/Au:N/C:N/I:N/A:P",
  "CvssV3": "CVSS:3.1/AV:N/AC:L/PR:L/UI:N/S:U/C:N/I:N/A:H",
  "UUID": "33793b64-8559-4fa4-adf6-40faabe727c6"
}